<?xml version="1.0" encoding="UTF-8" ?>
<testsuites errors="0"
            failures="1"
            tests="1">

  <testsuite name="unittest-failure"
    errors="0" failures="1" hostname="" id="" package="unittest-failure" skipped="0"
    tests="1" time="0.002000" timestamp="Mon, 24 Jul 2017 05:58:51 GMT">
  
    <testcase name="demoTest" classname="unittest-failure" time="0.002000" assertions="0"><failure message="AssertionError: 1 == 0 - expected &quot;0&quot; but got: &quot;1&quot;">    at Object.demoTest (/Users/Sneha/Documents/nightwatch-0.9.16/test/asynchookstests/unittest-failure/unittest-failure.js:5:12)
    at Object.&lt;anonymous&gt; (/Users/Sneha/Documents/nightwatch-0.9.16/lib/util/utils.js:35:8)
    at Module.callAsync (/Users/Sneha/Documents/nightwatch-0.9.16/lib/runner/module.js:75:18)
    at /Users/Sneha/Documents/nightwatch-0.9.16/lib/runner/testcase.js:77:43
    at _combinedTickCallback (internal/process/next_tick.js:67:7)
    at process._tickCallback (internal/process/next_tick.js:98:9)</failure>
    </testcase>
  

  

  
  </testsuite>
</testsuites>
