<?xml version="1.0" encoding="UTF-8" ?>
<testsuites errors="1"
            failures="0"
            tests="1">

  <testsuite name="afterEach"
    errors="1" failures="0" hostname="" id="" package="afterEach" skipped="0"
    tests="1" time="0.02100" timestamp="Mon, 24 Jul 2017 05:58:50 GMT">
  
    <testcase name="demoTest" classname="afterEach" time="0.02100" assertions="1">

    
    </testcase>
  

  
    <system-err>
        Error while running [After Each / demoTest]:

  Error: Provided error afterEach
    at Object.afterEach (/Users/Sneha/Documents/nightwatch-0.9.16/test/asynchookstests/async-provide-error/afterEach.js:9:10)
    at TestSuite.&lt;anonymous&gt; (/Users/Sneha/Documents/nightwatch-0.9.16/lib/runner/testsuite.js:188:19)
    at TestSuite.makePromise (/Users/Sneha/Documents/nightwatch-0.9.16/lib/runner/testsuite.js:528:8)
    at Object.hooks.afterEach (/Users/Sneha/Documents/nightwatch-0.9.16/lib/runner/testsuite.js:173:17)
    at TestSuite.afterEach (/Users/Sneha/Documents/nightwatch-0.9.16/lib/runner/testsuite.js:438:21)
    at onSuccess (/Users/Sneha/Documents/nightwatch-0.9.16/lib/runner/testcase.js:89:25)
    at _fulfilled (/Users/Sneha/Documents/nightwatch-0.9.16/node_modules/q/q.js:834:54)
    at self.promiseDispatch.done (/Users/Sneha/Documents/nightwatch-0.9.16/node_modules/q/q.js:863:30)
    at Promise.promise.promiseDispatch (/Users/Sneha/Documents/nightwatch-0.9.16/node_modules/q/q.js:796:13)
    at /Users/Sneha/Documents/nightwatch-0.9.16/node_modules/q/q.js:604:44
    at runSingle (/Users/Sneha/Documents/nightwatch-0.9.16/node_modules/q/q.js:137:13)
    at flush (/Users/Sneha/Documents/nightwatch-0.9.16/node_modules/q/q.js:125:13)
    at _combinedTickCallback (internal/process/next_tick.js:67:7)
    at process._tickCallback (internal/process/next_tick.js:98:9)
    </system-err>
  

  
  </testsuite>
</testsuites>
